#VRML_SIM R2025a utf8

EXTERNPROTO "https://raw.githubusercontent.com/cyberbotics/webots/R2025a/projects/objects/backgrounds/protos/TexturedBackground.proto"
EXTERNPROTO "https://raw.githubusercontent.com/cyberbotics/webots/R2025a/projects/objects/backgrounds/protos/TexturedBackgroundLight.proto"
EXTERNPROTO "https://raw.githubusercontent.com/cyberbotics/webots/R2025a/projects/objects/floors/protos/RectangleArena.proto"
EXTERNPROTO "https://raw.githubusercontent.com/cyberbotics/webots/R2025a/projects/objects/factory/containers/protos/WoodenBox.proto"
EXTERNPROTO "https://raw.githubusercontent.com/cyberbotics/webots/R2025a/projects/objects/obstacles/protos/OilBarrel.proto"

WorldInfo {
}
Viewpoint {
  orientation -0.5773518682295149 -0.577350336176523 0.5773486031582173 4.188790305273232
  position -0.0003111482865085463 -9.492697915405872e-06 6.834121579394564
}
TexturedBackground {
}
TexturedBackgroundLight {
  castShadows FALSE
}
DEF arena RectangleArena {
  rotation 0 0 1 3.14159
  name "arena"
  floorSize 2 2
  floorTileSize 0.25 0.25
}
WoodenBox {
  translation -0.664274 -0.723577 0.09
  rotation 0 0 -1 -2.6180053071795863
  name "wooden box(2)"
  size 0.15 0.5 0.2
}
Solid {
  translation -0.812461 -0.311011 0.001
  children [
    Shape {
      appearance PBRAppearance {
        baseColor 0 1 0
        metalness 0
      }
      geometry Plane {
        size 0.35 0.1
      }
    }
  ]
  name "puntoA"
}
Solid {
  translation -0.438413 -0.810711 0.001
  children [
    Shape {
      appearance PBRAppearance {
        baseColor 1 0 0
        metalness 0
      }
      geometry Plane {
        size 0.1 0.35
      }
    }
  ]
  name "puntoB"
}
WoodenBox {
  translation -0.480019 -0.395135 0.09
  rotation 0 0 -1 -2.6180053071795863
  name "wooden box(1)"
  size 0.15 0.5 0.2
}
WoodenBox {
  translation 0.192336 -0.448634 0.09
  rotation 0 0 -1 1.57079
  name "wooden box(3)"
  size 0.15 0.5 0.2
}
WoodenBox {
  translation -0.558866 0.367178 0.09
  rotation 0 0 1 6.32203e-06
  name "wooden box(5)"
  size 0.15 0.5 0.2
}
WoodenBox {
  translation 0.158505 0.149019 0.09
  rotation 0 0 1 1.8326
  name "wooden box(6)"
  size 0.15 0.3 0.2
}
WoodenBox {
  translation 0.456984 0.0740005 0.09
  rotation 0 0 1 1.8326
  name "wooden box(13)"
  size 0.15 0.4 0.2
}
WoodenBox {
  translation 0.830378 0.0610227 0.09
  rotation 0 0 1 0.785405
  name "wooden box(12)"
  size 0.15 0.4 0.2
}
WoodenBox {
  translation 0.441742 0.563014 0.09
  rotation 0 0 1 2.0944
  name "wooden box(11)"
  size 0.15 0.4 0.2
}
WoodenBox {
  translation 0.22263 0.605804 0.09
  rotation 0 0 1 2.0944
  name "wooden box(9)"
  size 0.15 0.4 0.2
}
WoodenBox {
  translation -0.00855515 0.648494 0.09
  rotation 0 0 1 2.0944
  name "wooden box(8)"
  size 0.15 0.4 0.2
}
WoodenBox {
  translation -0.422751 0.544418 0.09
  rotation 0 0 1 1.5708
  name "wooden box(7)"
  size 0.15 0.4 0.2
}
WoodenBox {
  translation 0.328907 -0.639851 0.11
  rotation 0 0 1 -2.356185307179586
  name "wooden box(10)"
  size 0.15 0.15 0.15
}
WoodenBox {
  translation -0.221889 -0.514428 0.11
  rotation 0 0 -1 2.09439
  name "wooden box(16)"
  size 0.15 0.15 0.15
}
WoodenBox {
  translation 0.596831 -0.570742 0.11
  rotation 0 0 1 -2.356185307179586
  name "wooden box(15)"
  size 0.15 0.15 0.15
}
WoodenBox {
  translation -0.367612 0.351574 0.11
  rotation 0 0 1 -2.356185307179586
  name "wooden box(14)"
  size 0.15 0.15 0.15
}
WoodenBox {
  translation -0.238326 -0.332879 0.09
  rotation 0 0 1 -2.0943853071795866
  name "wooden box(4)"
  size 0.15 0.5 0.2
}
OilBarrel {
  translation -0.80659 -0.523128 0.1
  height 0.2
  radius 0.06
}
OilBarrel {
  translation -0.455267 0.0837392 0.1
  name "oil barrel(2)"
  height 0.2
  radius 0.06
}
OilBarrel {
  translation 0.521129 -0.0459449 0.1
  name "oil barrel(19)"
  height 0.2
  radius 0.06
}
OilBarrel {
  translation 0.845473 -0.142668 0.1
  name "oil barrel(21)"
  height 0.2
  radius 0.06
}
OilBarrel {
  translation -0.33979 -0.434237 0.1
  name "oil barrel(22)"
  height 0.2
  radius 0.06
}
OilBarrel {
  translation -0.401504 -0.536115 0.1
  name "oil barrel(25)"
  height 0.2
  radius 0.06
}
OilBarrel {
  translation 0.457145 -0.571814 0.1
  name "oil barrel(24)"
  height 0.2
  radius 0.06
}
OilBarrel {
  translation 0.49862 -0.476454 0.1
  name "oil barrel(23)"
  height 0.2
  radius 0.06
}
OilBarrel {
  translation 0.0172242 -0.014284 0.1
  name "oil barrel(20)"
  height 0.2
  radius 0.06
}
OilBarrel {
  translation 0.638188 0.522627 0.1
  name "oil barrel(13)"
  height 0.2
  radius 0.06
}
OilBarrel {
  translation 0.937338 0.126693 0.1
  name "oil barrel(26)"
  height 0.2
  radius 0.06
}
OilBarrel {
  translation -0.0132783 0.483529 0.1
  name "oil barrel(18)"
  height 0.2
  radius 0.06
}
OilBarrel {
  translation 0.718184 0.61196 0.1
  name "oil barrel(17)"
  height 0.2
  radius 0.06
}
OilBarrel {
  translation 0.657657 0.719679 0.1
  name "oil barrel(16)"
  height 0.2
  radius 0.06
}
OilBarrel {
  translation -0.615678 0.674503 0.1
  name "oil barrel(15)"
  height 0.2
  radius 0.06
}
OilBarrel {
  translation -0.697838 0.59694 0.1
  name "oil barrel(14)"
  height 0.2
  radius 0.06
}
OilBarrel {
  translation -0.448496 -0.0233259 0.1
  name "oil barrel(12)"
  height 0.2
  radius 0.06
}
OilBarrel {
  translation -0.37187 -0.117471 0.1
  name "oil barrel(11)"
  height 0.2
  radius 0.06
}
OilBarrel {
  translation -0.37187 -0.117471 0.1
  name "oil barrel(10)"
  height 0.2
  radius 0.06
}
OilBarrel {
  translation -0.701732 -0.516404 0.1
  name "oil barrel(9)"
  height 0.2
  radius 0.06
}
OilBarrel {
  translation -0.912577 -0.530453 0.1
  name "oil barrel(1)"
  height 0.2
  radius 0.06
}
OilBarrel {
  translation -0.937385 -0.745806 0.1
  name "oil barrel(3)"
  height 0.2
  radius 0.06
}
OilBarrel {
  translation -0.876587 -0.83451 0.1
  name "oil barrel(7)"
  height 0.2
  radius 0.06
}
OilBarrel {
  translation -0.937748 -0.9294 0.1
  name "oil barrel(8)"
  height 0.2
  radius 0.06
}
OilBarrel {
  translation -0.877761 -0.628004 0.1
  name "oil barrel(4)"
  height 0.2
  radius 0.06
}
OilBarrel {
  translation -0.823858 -0.732199 0.1
  name "oil barrel(5)"
  height 0.2
  radius 0.06
}
OilBarrel {
  translation -0.759715 -0.625642 0.1
  name "oil barrel(6)"
  height 0.2
  radius 0.06
}
Robot {
  translation -0.811657 -0.310466 0.03
  rotation 0 0 1 1.5708
  children [
    Display {
      width 128
      height 128
    }
    Compass {
    }
    GPS {
    }
    DEF Cuerpo Shape {
      appearance PBRAppearance {
        baseColor 0.7 0.4 0.7
        metalness 0
      }
      geometry Cylinder {
        height 0.05
        radius 0.04
      }
    }
    HingeJoint {
      jointParameters HingeJointParameters {
        position 6999.907868847276
        axis 0 1 0
        anchor -0.02 -0.04001600000000001 -0.019928300000000003
      }
      device [
        RotationalMotor {
          name "ruedaDDown"
        }
      ]
      endPoint Solid {
        translation -0.0199999719965029 -0.040016003294127966 -0.019928955349477
        rotation 0.9535378239031935 0.2131172385627026 -0.21294755460763196 1.617559144394296
        children [
          DEF Rueda Shape {
            appearance PBRAppearance {
              baseColor 0 0 0
              metalness 0
            }
            geometry Cylinder {
              height 0.01
              radius 0.01
            }
          }
        ]
        name "ruedaDDown"
        boundingObject USE Rueda
        physics Physics {
        }
      }
    }
    HingeJoint {
      jointParameters HingeJointParameters {
        position 6994.163820403943
        axis 0 1 0
        anchor 0.020000001755814678 -0.040000000050413036 -0.019998564911008935
      }
      device [
        RotationalMotor {
          name "ruedaDUp"
        }
      ]
      endPoint Solid {
        translation 0.019998594196844077 -0.039999995876734 -0.02000062152071422
        rotation -0.7988373627137684 -0.425357245154341 0.42535876848517096 4.489652282881341
        children [
          USE Rueda
        ]
        name "ruedaDUp"
        boundingObject USE Rueda
        physics Physics {
        }
      }
    }
    HingeJoint {
      jointParameters HingeJointParameters {
        position 6192.144052832234
        axis 0 1 0
        anchor 0.02000000080276699 0.040000000642520184 -0.019999261719725873
      }
      device [
        RotationalMotor {
          name "ruedaIUp"
        }
      ]
      endPoint Solid {
        translation 0.019999854600083238 0.040000004214549335 -0.01999794440075764
        rotation 0.022959185149211022 -0.7069190921585282 0.7069216879959522 3.09568245272151
        children [
          USE Rueda
        ]
        name "ruedaIUp"
        boundingObject USE Rueda
        physics Physics {
        }
      }
    }
    HingeJoint {
      jointParameters HingeJointParameters {
        position 6184.357773312186
        axis 0 1 0
        anchor -0.019999999353749433 0.04000000111386122 -0.019998557752930867
      }
      device [
        RotationalMotor {
          name "ruedaIDown"
        }
      ]
      endPoint Solid {
        translation -0.02000242840182332 0.03999999760470765 -0.019999187096753798
        rotation 0.5263454922593375 0.6012311529436756 -0.6012333353268879 2.1725933452165855
        children [
          USE Rueda
        ]
        name "ruedaIDown"
        boundingObject USE Rueda
        physics Physics {
        }
      }
    }
    Lidar {
      translation 0 0 0.03
      children [
        DEF Sensor Shape {
          appearance PBRAppearance {
            metalness 0
          }
          geometry Sphere {
            radius 0.007
          }
        }
      ]
      name "LIDAR"
      boundingObject USE Sensor
      physics Physics {
      }
      horizontalResolution 360
      fieldOfView 6.28
      numberOfLayers 1
      maxRange 0.5
    }
  ]
  name "robot_universidad"
  boundingObject USE Cuerpo
  physics Physics {
  }
  controller "evasion_LIDAR"
}
