#VRML_SIM R2025a utf8

EXTERNPROTO "https://raw.githubusercontent.com/cyberbotics/webots/R2025a/projects/objects/backgrounds/protos/TexturedBackground.proto"
EXTERNPROTO "https://raw.githubusercontent.com/cyberbotics/webots/R2025a/projects/objects/backgrounds/protos/TexturedBackgroundLight.proto"
EXTERNPROTO "https://raw.githubusercontent.com/cyberbotics/webots/R2025a/projects/objects/floors/protos/RectangleArena.proto"
EXTERNPROTO "https://raw.githubusercontent.com/cyberbotics/webots/R2025a/projects/objects/factory/containers/protos/WoodenBox.proto"

WorldInfo {
}
Viewpoint {
  orientation -0.613525042937318 0.444753954286836 0.6525189206720254 2.25589523118308
  position 0.06228754231139264 -0.23178809637534933 5.840087718096504
}
TexturedBackground {
}
TexturedBackgroundLight {
}
DEF arena RectangleArena {
  name "arena"
  floorSize 2 2
  floorTileSize 0.25 0.25
}
WoodenBox {
  translation -0.127419 0.68774 0.05
  name "wooden box(3)"
  size 0.5 0.2 0.25
}
WoodenBox {
  translation -0.607419 -0.23226 0.05
  rotation 0 0 1 0.785398
  name "wooden box(1)"
  size 0.5 0.2 0.25
}
WoodenBox {
  translation 0.432736 -0.187198 0.05
  rotation 0 0 1 1.5708
  name "wooden box(2)"
  size 0.05 0.75 0.2
}
Robot {
  translation 0.89 -0.8 0
  children [
    Display {
      width 128
      height 128
    }
    Compass {
    }
    GPS {
    }
    DEF Cuerpo Shape {
      appearance PBRAppearance {
        baseColor 0.7 0.4 0.7
        metalness 0
      }
      geometry Cylinder {
        height 0.05
        radius 0.04
      }
    }
    HingeJoint {
      jointParameters HingeJointParameters {
        position 6999.907868847276
        axis 0 1 0
        anchor -0.02 -0.04001600000000001 -0.019928300000000003
      }
      device [
        RotationalMotor {
          name "ruedaDDown"
        }
      ]
      endPoint Solid {
        translation -0.0199999719965029 -0.040016003294127966 -0.019928955349477
        rotation 0.9535378239031931 0.21311723856270254 -0.21294755460763412 1.617559144394304
        children [
          DEF Rueda Shape {
            appearance PBRAppearance {
              baseColor 0 0 0
              metalness 0
            }
            geometry Cylinder {
              height 0.01
              radius 0.01
            }
          }
        ]
        name "ruedaDDown"
        boundingObject USE Rueda
        physics Physics {
        }
      }
    }
    HingeJoint {
      jointParameters HingeJointParameters {
        position 6994.163820403943
        axis 0 1 0
        anchor 0.020000001755814678 -0.040000000050413036 -0.019998564911008935
      }
      device [
        RotationalMotor {
          name "ruedaDUp"
        }
      ]
      endPoint Solid {
        translation 0.01999859419684407 -0.039999995876734 -0.020000621520714218
        rotation -0.7988373627137685 -0.4253572451543402 0.4253587684851711 4.489652282881344
        children [
          USE Rueda
        ]
        name "ruedaDUp"
        boundingObject USE Rueda
        physics Physics {
        }
      }
    }
    HingeJoint {
      jointParameters HingeJointParameters {
        position 6192.144052832234
        axis 0 1 0
        anchor 0.02000000080276699 0.040000000642520184 -0.019999261719725873
      }
      device [
        RotationalMotor {
          name "ruedaIUp"
        }
      ]
      endPoint Solid {
        translation 0.019999854600083238 0.040000004214549335 -0.019997944400757656
        rotation 0.022959185149212042 -0.7069190921585166 0.706921687995964 3.095682452721512
        children [
          USE Rueda
        ]
        name "ruedaIUp"
        boundingObject USE Rueda
        physics Physics {
        }
      }
    }
    HingeJoint {
      jointParameters HingeJointParameters {
        position 6184.357773312186
        axis 0 1 0
        anchor -0.019999999353749433 0.04000000111386122 -0.019998557752930867
      }
      device [
        RotationalMotor {
          name "ruedaIDown"
        }
      ]
      endPoint Solid {
        translation -0.02000242840182332 0.03999999760470765 -0.019999187096753794
        rotation 0.5263454922593455 0.6012311529436596 -0.6012333353268969 2.172593345216603
        children [
          USE Rueda
        ]
        name "ruedaIDown"
        boundingObject USE Rueda
        physics Physics {
        }
      }
    }
    DistanceSensor {
      translation 0.04 0 0
      rotation 0 0 1 0.523599
      children [
        DEF Sensor Shape {
          appearance PBRAppearance {
            metalness 0
          }
          geometry Sphere {
            radius 0.007
          }
        }
      ]
      name "sensorIzq"
      boundingObject USE Sensor
      physics Physics {
      }
    }
    DistanceSensor {
      translation 0.04 0 0
      rotation 0 0 1 -0.523595307179586
      children [
        DEF Sensor Shape {
          appearance PBRAppearance {
            metalness 0
          }
          geometry Sphere {
            radius 0.007
          }
        }
      ]
      name "sensorDer"
      boundingObject USE Sensor
      physics Physics {
      }
    }
    Lidar {
      translation 0 0 0.03
      children [
        USE Sensor
      ]
      name "LIDAR"
      boundingObject USE Sensor
      physics Physics {
      }
      horizontalResolution 360
      fieldOfView 6.28
      numberOfLayers 1
      maxRange 0.5
    }
  ]
  name "robot_universidad"
  boundingObject USE Cuerpo
  physics Physics {
  }
  controller "evasion_LIDAR"
}
