#VRML_SIM R2025a utf8

EXTERNPROTO "https://raw.githubusercontent.com/cyberbotics/webots/R2025a/projects/objects/backgrounds/protos/TexturedBackground.proto"
EXTERNPROTO "https://raw.githubusercontent.com/cyberbotics/webots/R2025a/projects/objects/backgrounds/protos/TexturedBackgroundLight.proto"
EXTERNPROTO "https://raw.githubusercontent.com/cyberbotics/webots/R2025a/projects/objects/floors/protos/RectangleArena.proto"
EXTERNPROTO "https://raw.githubusercontent.com/cyberbotics/webots/R2025a/projects/objects/factory/containers/protos/WoodenBox.proto"

WorldInfo {
}
Viewpoint {
  orientation -0.5773502691896258 0.5773502691896258 0.5773502691896258 2.0944
  position 0.0004047828585154424 6.075970267894158e-06 3.014918349459763
}
TexturedBackground {
}
TexturedBackgroundLight {
}
RectangleArena {
  floorSize 1.5 1.5
  floorTileSize 0.25 0.25
}
WoodenBox {
  translation -0.146566 -0.472214 0.05
  rotation 0 0 1 -0.523595307179586
  size 0.1 0.1 0.1
}
WoodenBox {
  translation 0.52242 0.183249 0.05
  rotation 0 0 1 -2.094395307179586
  name "wooden box(2)"
  size 0.1 0.1 0.1
}
WoodenBox {
  translation -0.492381 0.42477 0.05
  rotation 0 0 -1 1.28282
  name "wooden box(1)"
  size 0.1 0.1 0.1
}
Robot {
  translation 0 0 0.03
  children [
    DEF Cuerpo Shape {
      appearance PBRAppearance {
        baseColor 0.7 0.4 0.7
        metalness 0
      }
      geometry Cylinder {
        height 0.05
        radius 0.04
      }
    }
    HingeJoint {
      jointParameters HingeJointParameters {
        position 2209.8974373419237
        axis 0 1 0
        anchor -0.02 -0.04001600000000001 -0.019928300000000003
      }
      device [
        RotationalMotor {
          name "ruedaDDown"
        }
      ]
      endPoint Solid {
        translation -0.01999949625412059 -0.040016003294127966 -0.01992787987237436
        rotation 0.4953987390266386 -0.6144839113890458 0.6139947980356477 2.2210392802769765
        children [
          DEF Rueda Shape {
            appearance PBRAppearance {
              baseColor 0 0 0
              metalness 0
            }
            geometry Cylinder {
              height 0.01
              radius 0.01
            }
          }
        ]
        name "ruedaDDown"
        boundingObject USE Rueda
        physics Physics {
        }
      }
    }
    HingeJoint {
      jointParameters HingeJointParameters {
        position 2194.6690326691178
        axis 0 1 0
        anchor 0.020000001755814678 -0.040000000050413036 -0.019998564911008935
      }
      device [
        RotationalMotor {
          name "ruedaDUp"
        }
      ]
      endPoint Solid {
        translation 0.019997525160767304 -0.039999995876734 -0.01999884301657689
        rotation -0.4750886456953989 -0.6222089545556717 0.6222112146225346 4.028631085938773
        children [
          USE Rueda
        ]
        name "ruedaDUp"
        boundingObject USE Rueda
        physics Physics {
        }
      }
    }
    HingeJoint {
      jointParameters HingeJointParameters {
        position 2152.4682287218234
        axis 0 1 0
        anchor 0.02000000080276699 0.040000000642520184 -0.019999261719725873
      }
      device [
        RotationalMotor {
          name "ruedaIUp"
        }
      ]
      endPoint Solid {
        translation 0.020000394760543747 0.040000004214549335 -0.019997996215178716
        rotation -0.16952533585626076 0.6968707142010412 -0.696873279866399 3.4774490845666826
        children [
          USE Rueda
        ]
        name "ruedaIUp"
        boundingObject USE Rueda
        physics Physics {
        }
      }
    }
    HingeJoint {
      jointParameters HingeJointParameters {
        position 2144.6819420861616
        axis 0 1 0
        anchor -0.019999999353749433 0.04000000111386122 -0.019998557752930867
      }
      device [
        RotationalMotor {
          name "ruedaIDown"
        }
      ]
      endPoint Solid {
        translation -0.02000247703220232 0.03999999760470765 -0.019998160943559957
        rotation -0.3699826385095944 -0.6569283453571554 0.6569307393232474 3.850319508145244
        children [
          USE Rueda
        ]
        name "ruedaIDown"
        boundingObject USE Rueda
        physics Physics {
        }
      }
    }
    DistanceSensor {
      translation 0.04 0 0
      rotation 0 0 1 0.523599
      children [
        DEF Sensor Shape {
          appearance PBRAppearance {
            metalness 0
          }
          geometry Sphere {
            radius 0.007
          }
        }
      ]
      name "sensorIzq"
      boundingObject USE Sensor
      physics Physics {
      }
    }
    DistanceSensor {
      translation 0.04 0 0
      rotation 0 0 1 -0.523595307179586
      children [
        DEF Sensor Shape {
          appearance PBRAppearance {
            metalness 0
          }
          geometry Sphere {
            radius 0.007
          }
        }
      ]
      name "sensorDer"
      boundingObject USE Sensor
      physics Physics {
      }
    }
    Lidar {
      translation 0 0 0.03
      children [
        USE Sensor
      ]
      name "LIDAR"
      boundingObject USE Sensor
      physics Physics {
      }
      horizontalResolution 360
      fieldOfView 6.28
      numberOfLayers 1
      maxRange 0.5
    }
  ]
  name "robot_universidad"
  boundingObject USE Cuerpo
  physics Physics {
  }
  controller "evasion_LIDAR"
}
